<?xml version="1.0"?>
<robot name="car" xmlns:xacro="http://www.ros.org/wiki/xacro">
  <xacro:include filename="$(find car_description)/urdf/_d435.urdf.xacro"/>
  <xacro:include filename="$(find car_description)/urdf/common.xacro"/>

  <material name="black">
    <color rgba="0.1 0.1 0.1 1"/>
  </material>

  <material name="plastic">
    <color rgba="1 1 1 0.25"/>
  </material>

  <material name="imu">
    <color rgba="0.2 0.5 0.1 1"/>
  </material>

  <material name="grey">
    <color rgba="0.75 0.75 0.75 1"/>
  </material>

  <material name="white">
    <color rgba="0.95 0.95 0.95 1"/>
  </material>		
  
  <link name="base_link">
    <visual>
      <origin rpy="0.0 0 0" xyz="0.135 0 0.01"/>
      <geometry>
        <mesh filename="package://car_description/meshes/chasi.dae"/>
      </geometry>
      <material name="black"/>
    </visual>
    <collision>
      <origin rpy="0.0 0 0" xyz="0.135 0 0.01"/>
      <geometry>
        <mesh filename="package://car_description/meshes/chasi.dae"/>
      </geometry>
    </collision>
  </link>

  <link name="board">
    <visual>
      <origin rpy="0.0 0 0" xyz="0.115 0 0"/>
      <geometry>
        <mesh filename="package://car_description/meshes/board.dae"/>
      </geometry>
      <material name="plastic"/>
    </visual>
    <collision>
      <origin rpy="0.0 0 0" xyz="0.115 0 0"/>
      <geometry>
        <mesh filename="package://car_description/meshes/board.dae"/>
      </geometry>
    </collision>
    <inertial>
      <origin rpy="0.0 0 0" xyz="0.115 0 0"/>
      <mass value="1.0"/>
      <inertia ixx="0.00213542" ixy="0.0" ixz="0.0" iyy="0.01235417" iyz="0.0" izz="0.01448542"/>
    </inertial>
  </link>

  <link name="camera_board">
    <visual>
      <origin rpy="0.0 0 0" xyz="0 0 0"/>
      <geometry>
        <mesh filename="package://car_description/meshes/camera_board.dae"/>
      </geometry>
      <material name="plastic"/>
    </visual>
    <collision>
      <origin rpy="0.0 0 0" xyz="0 0 0"/>
      <geometry>
        <mesh filename="package://car_description/meshes/camera_board.dae"/>
      </geometry>
    </collision>
    <inertial>
      <origin rpy="0.0 0 0" xyz="0 0 0"/>
      <mass value="0.1"/>
      <inertia ixx="0.00014165" ixy="0.0" ixz="0.0" iyy="0.00006758" iyz="0.0" izz="0.00020865"/>
    </inertial>
  </link>

  <link name="laser">
    <visual>
      <origin rpy="0.0 0 0" xyz="0 0 -0.02"/>
      <geometry>
        <mesh filename="package://car_description/meshes/laser.dae"/>
      </geometry>
      <material name="black"/>
    </visual>
    <collision>
       <origin rpy="0.0 0 0" xyz="0 0 -0.02"/>
      <geometry>
        <mesh filename="package://car_description/meshes/laser.dae"/>
      </geometry>
    </collision>
    <inertial>
      <mass value="0.1"/>
      <inertia ixx="0.00005965" ixy="0.0" ixz="0.0" iyy="0.00005759" iyz="0.0" izz="0.00009268"/>
    </inertial>
  </link>

  <xacro:macro name="wheel" params="name">
    <link name="${name}">
      <visual>
        <origin rpy="0.0 0 0" xyz="0 0 0"/>
        <geometry>
          <mesh filename="package://car_description/meshes/wheel.dae"/>
        </geometry>
        <material name="black"/>
      </visual>
      <collision>
        <geometry>
          <mesh filename="package://car_description/meshes/wheel.dae"/>
        </geometry>
        <minDepth>0.005</minDepth>
        <maxContacts>1</maxContacts>
        <max_contacts>1</max_contacts>
        <surface>
          <friction>
            <ode>
              <mu>1.0</mu>
              <mu2>1.0</mu2>
              <fdir1>0 0 1</fdir1>
              <slip1>0.0</slip1>
              <slip2>0.0</slip2>
            </ode>
          </friction>
          <contact>
            <ode>
              <min_depth>0.005</min_depth>
              <kp>1e8</kp>
            </ode>
          </contact>
        </surface>
      </collision>
      <inertial>
        <mass value="0.05"/>
        <inertia ixx="0.00001793" ixy="0.0" ixz="0.0" iyy="0.00002867" iyz="0.0" izz="0.00001813"/>
      </inertial>
    </link>
  </xacro:macro>

  <xacro:wheel name="wheel_fr"/>
  <xacro:wheel name="wheel_fl"/>
  <xacro:wheel name="wheel_br"/>
  <xacro:wheel name="wheel_bl"/>

  <link name="axis_fl">
    <visual>
      <origin rpy="0.0 0 0" xyz="0 0 0"/>
      <geometry>
        <box size="0.001 0.001 0.001"/>
      </geometry>
      <material name="black"/>
    </visual>
    <collision>
      <geometry>
        <box size="0.001 0.001 0.001"/>
      </geometry>
    </collision>
    <inertial>
      <mass value="0.1"/>
      <inertia ixx="0.00000002" ixy="0.0" ixz="0.0" iyy="0.00000002" iyz="0.0" izz="0.00000002"/>
    </inertial>
  </link>

  <link name="axis_fr">
    <visual>
      <origin rpy="0.0 0 0" xyz="0 0 0"/>
      <geometry>
        <box size="0.001 0.001 0.001"/>
      </geometry>
      <material name="black"/>
    </visual>
    <collision>
      <geometry>
        <box size="0.001 0.001 0.001"/>
      </geometry>
    </collision>
    <inertial>
      <mass value="0.1"/>
      <inertia ixx="0.00000002" ixy="0.0" ixz="0.0" iyy="0.00000002" iyz="0.0" izz="0.00000002"/>
    </inertial>
  </link>

  <link name="imu">
    <visual>
      <geometry>
        <box size="0.066 0.064 0.01"/>
      </geometry>
      <origin rpy="0 0 0" xyz="0 0 0"/> 
      <material name="imu"/>     
    </visual>
    <collision>
      <geometry>
        <box size="0.066 0.064 0.01"/>
      </geometry>
    </collision>
    <inertial>
      <mass value="0.2"/>
      <inertia ixx="0.00006993" ixy="0.0" ixz="0.0" iyy="0.00007427" iyz="0.0" izz="0.00014087"/>
    </inertial>
  </link>

  <link name="marker">
    <visual>
      <geometry>
        <mesh filename="package://car_description/meshes/marker.dae"/>
      </geometry>
      <origin rpy="0 0 1.5708" xyz="0 0 0"/>
          
    </visual>
    <collision>
      <geometry>
        <box size="0.03 0.03 0.000001"/>
      </geometry>
    </collision>
    <inertial>
      <mass value="0.001"/>
      <inertia ixx="0.00000008" ixy="0.0" ixz="0.0" iyy="0.00000008" iyz="0.0" izz="0.00000015"/>
    </inertial>
  </link>

  <link name="support_l">
    <visual>
      <geometry>
        <cylinder length="0.22" radius="0.004"/>
      </geometry>
      <origin rpy="0 0 0" xyz="0 0 0"/>
      <material name="black"/>      
    </visual>
    <collision>
      <geometry>
        <cylinder length="0.22" radius="0.004"/>
      </geometry>
    </collision>
    <inertial>
      <mass value="0.001"/>
      <inertia ixx="0.00000404" ixy="0.0" ixz="0.0" iyy="0.00000404" iyz="0.0" izz="0.00000001"/>
    </inertial>
  </link>

  <link name="support_r">
    <visual>
      <geometry>
        <cylinder length="0.22" radius="0.004"/>
      </geometry>
      <origin rpy="0 0 0" xyz="0 0 0"/>
      <material name="black"/>      
    </visual>
    <collision>
      <geometry>
        <cylinder length="0.22" radius="0.004"/>
      </geometry>
    </collision>
    <inertial>
      <mass value="0.001"/>
      <inertia ixx="0.00000404" ixy="0.0" ixz="0.0" iyy="0.00000404" iyz="0.0" izz="0.00000001"/>
    </inertial>
  </link>

  <!-- BNO055 -->
  <link name="bno055">
  </link>

  <!-- front camera -->
  <xacro:property name="front_camera_name" value="camera"/>

  <sensor_d435 parent="camera_board" sensor_name="camera">
    <origin xyz="0.03 0 0.025" rpy="0 0.2 0"/>
  </sensor_d435>

  <sensor_d435 parent="camera_board" sensor_name="rear_camera">
    <origin xyz="-0.02 0 0.025" rpy="0 0.2 3.141"/>
  </sensor_d435>

  <joint name="joint_board_to_bno055" type="fixed">
      <parent link="board"/>
      <child link="bno055"/>
      <origin xyz="0.235 0.0 0.023" rpy="0 0 1.5708"/>
  </joint>

  <joint name="base_link_board" type="fixed">
    <parent link="base_link"/>
    <child link="board"/>
    <origin xyz="0 0 0.07"/>
  </joint>

  <joint name="board_cameraboard" type="fixed">
    <parent link="board"/>
    <child link="camera_board"/>
    <origin xyz="-0.025 0 0.15"/>
  </joint>

  <joint name="board_laser" type="fixed">
    <parent link="board"/>
    <child link="laser"/>
    <origin rpy="0 0 3.14159" xyz="0.185 0 0.025"/>
  </joint>

  <joint name="board_imu" type="fixed">
    <parent link="board"/>
    <child link="imu"/>
    <origin xyz="0.07 -0.017 0"/>
  </joint>

  <joint name="board_marker" type="fixed">
    <parent link="board"/>
    <child link="marker"/>
    <origin xyz="0.30 0 0.0025"/>
  </joint>

  <joint name="frontwheel_steering_left" type="revolute">
    <axis xyz="0 0 1"/>
    <limit effort="1000.0" lower="-0.55" upper="0.55" velocity="2"/>
    <parent link="base_link"/>
    <child link="axis_fl"/>
    <origin xyz="0.255 0.08 0.03"/>
  </joint>

  <joint name="frontwheel_steering_right" type="revolute">
    <axis xyz="0 0 1"/>
    <limit effort="1000.0" lower="-0.55" upper="0.55" velocity="2"/>
    <parent link="base_link"/>
    <child link="axis_fr"/>
    <origin xyz="0.255 -0.08 0.03"/>
  </joint>

  <joint name="frontwheel_left" type="revolute">
    <axis xyz="0 1 0"/>
    <anchor xyz="0 0 0"/>
    <parent link="axis_fl"/>
    <child link="wheel_fl"/>
    <origin xyz="0 0 0"/>
    <limit effort="0.1" lower="-1000000000000.0" upper="1000000000000.0" velocity="124"/>
  </joint>

  <joint name="frontwheel_right" type="revolute">
    <axis xyz="0 1 0"/>
    <parent link="axis_fr"/>
    <child link="wheel_fr"/>
    <origin xyz="0 0 0"/>
    <limit effort="0.1" lower="-1000000000000.0" upper="1000000000000.0" velocity="124"/>
  </joint>

   <joint name="rearwheel_left" type="revolute">
    <axis xyz="0 1 0"/>
    <parent link="base_link"/>
    <child link="wheel_bl"/>
    <origin xyz="0 0.085 0.03"/>
    <limit effort="0.1" lower="-1000000000000.0" upper="1000000000000.0" velocity="124"/>
   </joint>

  <joint name="rearwheel_right" type="revolute">
    <axis xyz="0 1 0"/>
    <parent link="base_link"/>
    <child link="wheel_br"/>
    <origin xyz="0 -0.085 0.03"/>
    <limit effort="0.1" lower="-1000000000000.0" upper="1000000000000.0" velocity="124"/>
  </joint>

  <joint name="board_support_l" type="fixed">
    <parent link="board"/>
    <child link="support_l"/>
    <origin xyz="-0.024000 0.053000 0.112000"/>
  </joint>

  <joint name="board_support_r" type="fixed">
    <parent link="board"/>
    <child link="support_r"/>
    <origin xyz="-0.024000 -0.053000 0.112000"/>
  </joint>

  <transmission name="steering_front_left_wheel">
    <type>transmission_interface/SimpleTransmission</type>
    <joint name="frontwheel_steering_left">
      <hardwareInterface>hardware_interface/EffortJointInterface</hardwareInterface>
    </joint>
    <actuator name="front_left_steering_motor">
      <hardwareInterface>hardware_interface/EffortJointInterface</hardwareInterface>
      <mechanicalReduction>1</mechanicalReduction>
    </actuator>
  </transmission>

  <transmission name="steering_front_right_wheel">
    <type>transmission_interface/SimpleTransmission</type>
    <joint name="frontwheel_steering_right">
      <hardwareInterface>hardware_interface/EffortJointInterface</hardwareInterface>
    </joint>
    <actuator name="front_right_steering_motor">
      <hardwareInterface>hardware_interface/EffortJointInterface</hardwareInterface>
      <mechanicalReduction>1</mechanicalReduction>
    </actuator>
  </transmission>

  <transmission name="tran_front_left_wheel">
    <type>transmission_interface/SimpleTransmission</type>
    <joint name="frontwheel_left">
      <hardwareInterface>hardware_interface/EffortJointInterface</hardwareInterface>
    </joint>
    <actuator name="front_left_wheel_motor">
      <hardwareInterface>hardware_interface/EffortJointInterface</hardwareInterface>
      <mechanicalReduction>1</mechanicalReduction>
    </actuator>
  </transmission>

  <transmission name="tran_front_right_wheel">
    <type>transmission_interface/SimpleTransmission</type>
    <joint name="frontwheel_right">
      <hardwareInterface>hardware_interface/EffortJointInterface</hardwareInterface>
    </joint>
    <actuator name="front_right_wheel_motor">
      <hardwareInterface>hardware_interface/EffortJointInterface</hardwareInterface>
      <mechanicalReduction>1</mechanicalReduction>
    </actuator>
  </transmission>

  <transmission name="tran_rear_left">
    <type>transmission_interface/SimpleTransmission</type>
    <joint name="rearwheel_left">
      <hardwareInterface>hardware_interface/EffortJointInterface</hardwareInterface>
    </joint>
    <actuator name="rear_left_motor">
      <hardwareInterface>hardware_interface/EffortJointInterface</hardwareInterface>
      <mechanicalReduction>1</mechanicalReduction>
    </actuator>
  </transmission>

  <transmission name="tran_rear_right">
    <type>transmission_interface/SimpleTransmission</type>
    <joint name="rearwheel_right">
      <hardwareInterface>hardware_interface/EffortJointInterface</hardwareInterface>
    </joint>
    <actuator name="rear_right_motor">
      <hardwareInterface>hardware_interface/EffortJointInterface</hardwareInterface>
      <mechanicalReduction>1</mechanicalReduction>
    </actuator>
  </transmission>

  <gazebo reference="rearwheel_left">
    <implicitSpringDamper>true</implicitSpringDamper>
  </gazebo>
  <gazebo reference="rearwheel_right">
    <implicitSpringDamper>true</implicitSpringDamper>
  </gazebo>
  <gazebo reference="frontwheel_right">
    <implicitSpringDamper>true</implicitSpringDamper>
  </gazebo>
  <gazebo reference="frontwheel_left">
    <implicitSpringDamper>true</implicitSpringDamper>
  </gazebo>
  <gazebo reference="frontwheel_steering_right">
    <implicitSpringDamper>true</implicitSpringDamper>
  </gazebo>
  <gazebo reference="frontwheel_steering_left">
    <implicitSpringDamper>true</implicitSpringDamper>
  </gazebo>

  <gazebo>
    <plugin filename="libgazebo_ros_control.so" name="gazebo_ros_control">
      <robotNamespace>model_car</robotNamespace>
    </plugin>
  </gazebo>

  <gazebo>
    <plugin name="model_car_ground_truth" filename="libgazebo_ros_p3d.so">
      <frameName>map</frameName>
      <bodyName>base_link</bodyName>
      <topicName>/simulation/odom_ground_truth</topicName>
      <updateRate>30.0</updateRate>
    </plugin>
  </gazebo>

  <gazebo>
    <plugin filename="libhector_gazebo_ros_imu.so" name="autominy_imu">
      <updateRate>100.0</updateRate>
      <robotNamespace>/</robotNamespace>
      <bodyName>imu</bodyName>
      <frameId>imu</frameId>
      <topicName>sensors/imu</topicName>
      <accelOffset>0 0 0</accelOffset>
      <accelDrift>0.5 0.5 0.5</accelDrift>
      <accelGaussianNoise>0.15 0.15 0.1</accelGaussianNoise>
      <rateOffset>0 0 0</rateOffset>
      <rateDrift>0.0 0.0 0.0</rateDrift>
      <rateGaussianNoise>0.005 0.005 0.0015</rateGaussianNoise>
      <headingOffset>0</headingOffset>
      <headingDrift>0.1</headingDrift>
      <headingGaussianNoise>0.05</headingGaussianNoise>
    </plugin>
  </gazebo>

  <gazebo reference="camera_depth_frame">
    <sensor type="depth" name="camera1">       
      <always_on>1</always_on>
      <visualize>true</visualize>
      <update_rate>15.0</update_rate>
      <camera>
        <pose>0 0 0 0 0.20 0</pose>
        <horizontal_fov>1.3900031938640904</horizontal_fov>
        <image>
          <width>640</width>
          <height>480</height>
          <format>L8</format>
        </image>
        <depth_camera>
        </depth_camera>
        <clip>
          <near>0.01</near>
          <far>50.0</far>
        </clip>
        <noise>
          <type>gaussian</type>
          <mean>0.0</mean>
          <stddev>0.007</stddev>
        </noise>
      </camera>
      <plugin name="camera_controller" filename="libgazebo_ros_openni_kinect.so">
        <alwaysOn>true</alwaysOn>
        <updateRate>15.0</updateRate>
        <cameraName>sensors/camera</cameraName>
        <frameName>camera_depth_optical_frame</frameName>
        <imageTopicName>infra1/image_rect_raw</imageTopicName>
        <cameraInfoTopicName>infra1/camera_info</cameraInfoTopicName>
        <depthImageTopicName>depth/image_rect_raw</depthImageTopicName>
        <pointCloudTopicName>depth/points</pointCloudTopicName>
        <depthImageCameraInfoTopicName>depth/camera_info</depthImageCameraInfoTopicName>            
        <pointCloudCutoff>0.4</pointCloudCutoff>                
        <hackBaseline>0.007</hackBaseline>
        <CxPrime>322.3056945800781</CxPrime>
        <Cx>322.3056945800781</Cx>
        <Cy>241.67051696777344</Cy>
        <focalLength>383.7944641113281</focalLength>
        <noise>
          <type>gaussian</type>
          <mean>0.0</mean>
          <stddev>0.01</stddev>
        </noise>
      </plugin>
    </sensor>
  </gazebo>

  <gazebo reference="camera_color_frame">
    <sensor type="camera" name="camera2">
      <update_rate>15.0</update_rate>
      <camera>
        <pose>0 0 0.02 0 0.20 0</pose>
        <horizontal_fov>0.95417536656506718</horizontal_fov>
        <image>
          <width>640</width>
          <height>480</height>
          <format>R8G8B8</format>
        </image>
        <clip>
          <near>0.01</near>
          <far>50.0</far>
        </clip>
        <noise>
          <type>gaussian</type>
          <mean>0.0</mean>
          <stddev>0.01</stddev>
        </noise>
      </camera>
      <plugin name="camera_controller2" filename="libgazebo_ros_camera.so">
        <alwaysOn>true</alwaysOn>
        <updateRate>15.0</updateRate>
        <cameraName>sensors/camera/color</cameraName>
        <imageTopicName>image_rect_color</imageTopicName>
        <cameraInfoTopicName>camera_info</cameraInfoTopicName>
        <frameName>camera_color_optical_frame</frameName>
        <hackBaseline>0.0193</hackBaseline>
        <distortionK1>0.0</distortionK1>
        <distortionK2>0.0</distortionK2>
        <distortionK3>0.0</distortionK3>
        <distortionT1>0.0</distortionT1>
        <distortionT2>0.0</distortionT2>
      </plugin>
    </sensor>
  </gazebo>

  <gazebo reference="laser">
    <sensor type="ray" name="rp_lidar_sensor">
      <pose>0 0 0 0 0 0</pose>
      <visualize>false</visualize>
      <update_rate>10</update_rate>
      <ray>
        <scan>
          <horizontal>
            <samples>360</samples>
            <min_angle>-3.14159</min_angle>
            <max_angle>3.14159</max_angle>
          </horizontal>
        </scan>
        <range>
          <min>0.15</min>
          <max>8.0</max>
          <resolution>0.05</resolution>
        </range>
        <noise>
          <type>gaussian</type>
          <mean>0.0</mean>
          <stddev>0.01</stddev>
        </noise>
      </ray>
      <plugin name="gazebo_ros_head_hokuyo_controller" filename="libgazebo_ros_laser.so">
        <topicName>/sensors/rplidar/scan</topicName>
        <frameName>laser</frameName>
      </plugin>
    </sensor>
  </gazebo>
  <gazebo reference="wheel_fl">
    <mu1>1.34</mu1>
    <mu2>1.34</mu2>
  </gazebo>
  <gazebo reference="wheel_fr">
    <mu1>1.34</mu1>
    <mu2>1.34</mu2>
  </gazebo>
  <gazebo reference="wheel_br">
    <mu1>1.34</mu1>
    <mu2>1.34</mu2>
  </gazebo>
  <gazebo reference="wheel_bl">
    <mu1>1.34</mu1>
    <mu2>1.34</mu2>
  </gazebo>

  <gazebo reference="support_r">
    <material>Gazebo/Black</material>
  </gazebo>

  <gazebo reference="support_l">
    <material>Gazebo/Black</material>
  </gazebo>
</robot>

